Workbook
Name Unarmed: datasheet!$L$28
Name CultTitle: CULTS!$X$160:$AK$162
Name ActionPoints: datasheet!$C$20
Name Head: datasheet!$C$29
Name Rank_BACK: CULTS!$H$160:$Q$162
Name MovementRate: #REF!
Name CURRENT_SIZ: 'PAGE 1'!$T$83
Name Deceit: datasheet!$L$14
Name Passion1: datasheet!$L$34
Name Endurance: datasheet!$L$16
Name Insight: datasheet!$L$20
Name Brawn: datasheet!$L$10
Name Rank: 'PAGE 2'!$H$160:$Q$162
Name Drive: datasheet!$L$15
Name BonusPoints: datasheet!$D$39
Name CURRENT_STR: 'PAGE 1'!$T$75
Name Rank_BACK: 'PAGE 2'!$H$160:$Q$162
Name TotalENC: CULTS!$BF$26
Name Burden: 'PAGE 2'!$BU$26
Name ArmourPenalty: 'PAGE 2'!$DF$26
Name Arm: datasheet!$C$32
Name CultRank: calculations!$B$147:$B$151
Name CultType_BACK: CULTS!$K$157:$AK$159
Name Stealth: datasheet!$L$26
Name CON: datasheet!$C$9
Name Abdomen: datasheet!$C$31
Name Passion3: datasheet!$L$36
Name InitBonus: datasheet!$C$25
Name NativeTongue: datasheet!$L$22
Name ExpModifier: datasheet!$C$21
Name Passion2: datasheet!$L$35
Name CURRENT_INT: 'PAGE 1'!$T$91
Name Willpower: datasheet!$L$29
Name AgeRange: datasheet!$D$36
Name CURRENT_DEX: 'PAGE 1'!$T$87
Name ArmourPenalty: CULTS!$DF$26
Name HealingRate: datasheet!$C$22
Name CultType_BACK: 'PAGE 2'!$K$157:$AK$159
Name NAME: datasheet!$C$2
Name CombatStyle1: datasheet!$L$30
Name FirstAid: datasheet!$L$18
Name Evade: datasheet!$L$17
Name CultType: calculations!$C$146:$G$146
Name Swim: datasheet!$L$27
Name INT: datasheet!$C$12
Name Height: #REF!
Name NamedRange1: datasheet!$D$37
Name Ride: datasheet!$L$24
Name TotalENC: 'PAGE 2'!$BF$26
Name Locale: datasheet!$L$21
Name Conceal: datasheet!$L$11
Name Sing: datasheet!$L$25
Name CURRENT_CHA: 'PAGE 1'!$T$99
Name CultRank_BACK: CULTS!$H$160:$Q$162
Name Burden: CULTS!$BU$26
Name CulturePoints: datasheet!$D$37
Name CULTS: calculations!$B$146:$G$151
Name Leg: datasheet!$C$33
Name Influence: datasheet!$L$19
Name Perception: datasheet!$L$23

Sheet HOW TO USE
A1: 1. Make a copy of this Google sheet 2. Enter in your data into Datasheet 3. Click on PAGE 1, 2, etc. for a nice sheet
A3: Many cells have dropdowns to choose premade options. Errors are shown if something custom is entered, but can be safely ignored. Just understand custom entries may not completely autofill
A5: For a more in depth How To, click the link below
A6: CLICK HERE

Sheet datasheet
B1: Character Info | F1: Fill in cells with this colour
B2: Character Name | C2: Anathaym | F2: Age | G2: 28 | O2: Career | P2: Warrior
B3: Player Name | C3: Adept_Austin | F3: Race | G3: Human | O3: Profession | P3: Scarlet Spear
B4: Culture | C4: Civilised | F4: Homeland | G4: Meeros | O4: Social Class | P4: Aristocracy
B6: Characteristics | F6: Standard Skills | O6: Professional Skills
B7: stats | C7: Total | D7: Racial Avg | F7: skills | G7: base | H7: culture | I7: career | J7: bonus | K7: other | L7: total | O7: skills | P7: base | Q7: culture | R7: career | S7: bonus | T7: other | U7: total
B8: STR | C8: 11 | D8: 11 | F8: Athletics | G8: =IFERROR(IFERROR(IFERROR(IFERROR(VLOOKUP(datasheet!F8, 'PAGE 1'!$AS$49:$BS$81,26,FALSE),VLOOKUP(datasheet!F8, 'PAGE 1'!$CB$49:$DB$81,26,FALSE)),VLOOKUP(datasheet!F8, 'PAGE 1'!$AS$127:$BS$159,26,FALSE)),VLOOKUP(datasheet!F8, 'PAGE 1'!$CB$127:$DB$159,26,FALSE)),"") -> 27 | K8: 17 | L8: =SUM(G8:K8) -> 44 | O8: Acrobatics | P8: =IFERROR(VLOOKUP(datasheet!O8,'PAGE 1'!$AS$88:$BS$120,26,FALSE),"") | U8: =SUM(P8:T8) -> 0
B9: CON | C9: 13 | D9: 11 | F9: Boating | G9: =IFERROR(IFERROR(IFERROR(IFERROR(VLOOKUP(datasheet!F9, 'PAGE 1'!$AS$49:$BS$81,26,FALSE),VLOOKUP(datasheet!F9, 'PAGE 1'!$CB$49:$DB$81,26,FALSE)),VLOOKUP(datasheet!F9, 'PAGE 1'!$AS$127:$BS$159,26,FALSE)),VLOOKUP(datasheet!F9, 'PAGE 1'!$CB$127:$DB$159,26,FALSE)),"") -> 24 | L9: =SUM(G9:K9) -> 24 | O9: Acting | P9: =IFERROR(VLOOKUP(datasheet!O9,'PAGE 1'!$AS$88:$BS$120,26,FALSE),"") | U9: =SUM(P9:T9) -> 0
B10: SIZ | C10: 10 | D10: 13 | F10: Brawn | G10: =IFERROR(IFERROR(IFERROR(IFERROR(VLOOKUP(datasheet!F10, 'PAGE 1'!$AS$49:$BS$81,26,FALSE),VLOOKUP(datasheet!F10, 'PAGE 1'!$CB$49:$DB$81,26,FALSE)),VLOOKUP(datasheet!F10, 'PAGE 1'!$AS$127:$BS$159,26,FALSE)),VLOOKUP(datasheet!F10, 'PAGE 1'!$CB$127:$DB$159,26,FALSE)),"") -> 21 | K10: 4 | L10: =SUM(G10:K10) -> 25 | O10: Art () | P10: =IFERROR(VLOOKUP(datasheet!O10,'PAGE 1'!$AS$88:$BS$120,26,FALSE),"") | U10: =SUM(P10:T10) -> 0
B11: DEX | C11: 16 | D11: 11 | F11: Conceal | G11: =IFERROR(IFERROR(IFERROR(IFERROR(VLOOKUP(datasheet!F11, 'PAGE 1'!$AS$49:$BS$81,26,FALSE),VLOOKUP(datasheet!F11, 'PAGE 1'!$CB$49:$DB$81,26,FALSE)),VLOOKUP(datasheet!F11, 'PAGE 1'!$AS$127:$BS$159,26,FALSE)),VLOOKUP(datasheet!F11, 'PAGE 1'!$CB$127:$DB$159,26,FALSE)),"") -> 23 | L11: =SUM(G11:K11) -> 23 | O11: Bureaucracy | P11: =IFERROR(VLOOKUP(datasheet!O11,'PAGE 1'!$AS$88:$BS$120,26,FALSE),"") | U11: =SUM(P11:T11) -> 0
B12: INT | C12: 14 | D12: 13 | F12: Customs (Meeros) | G12: =IFERROR(IFERROR(IFERROR(IFERROR(VLOOKUP(datasheet!F12, 'PAGE 1'!$AS$49:$BS$81,26,FALSE),VLOOKUP(datasheet!F12, 'PAGE 1'!$CB$49:$DB$81,26,FALSE)),VLOOKUP(datasheet!F12, 'PAGE 1'!$AS$127:$BS$159,26,FALSE)),VLOOKUP(datasheet!F12, 'PAGE 1'!$CB$127:$DB$159,26,FALSE)),"") -> 28 | K12: 46 | L12: =SUM(G12:K12) -> 74 | O12: Commerce | P12: =IFERROR(VLOOKUP(datasheet!O12,'PAGE 1'!$AS$88:$BS$120,26,FALSE),"") | U12: =SUM(P12:T12) -> 0
B13: POW | C13: 7 | D13: 11 | F13: Dance | G13: =IFERROR(IFERROR(IFERROR(IFERROR(VLOOKUP(datasheet!F13, 'PAGE 1'!$AS$49:$BS$81,26,FALSE),VLOOKUP(datasheet!F13, 'PAGE 1'!$CB$49:$DB$81,26,FALSE)),VLOOKUP(datasheet!F13, 'PAGE 1'!$AS$127:$BS$159,26,FALSE)),VLOOKUP(datasheet!F13, 'PAGE 1'!$CB$127:$DB$159,26,FALSE)),"") -> 25 | L13: =SUM(G13:K13) -> 25 | O13: Courtesy | P13: =IFERROR(VLOOKUP(datasheet!O13,'PAGE 1'!$AS$88:$BS$120,26,FALSE),"") -> 23 | T13: 15 | U13: =SUM(P13:T13) -> 38
B14: CHA | C14: 9 | D14: 11 | F14: Deceit | G14: =IFERROR(IFERROR(IFERROR(IFERROR(VLOOKUP(datasheet!F14, 'PAGE 1'!$AS$49:$BS$81,26,FALSE),VLOOKUP(datasheet!F14, 'PAGE 1'!$CB$49:$DB$81,26,FALSE)),VLOOKUP(datasheet!F14, 'PAGE 1'!$AS$127:$BS$159,26,FALSE)),VLOOKUP(datasheet!F14, 'PAGE 1'!$CB$127:$DB$159,26,FALSE)),"") -> 23 | K14: 5 | L14: =SUM(G14:K14) -> 28 | O14: Craft () | P14: =IFERROR(VLOOKUP(datasheet!O14,'PAGE 1'!$AS$88:$BS$120,26,FALSE),"") | U14: =SUM(P14:T14) -> 0
B15: total points | C15: =SUM(C8:C14) -> 80 | D15: =sum(D8:D14) -> 81 | F15: Drive | G15: =IFERROR(IFERROR(IFERROR(IFERROR(VLOOKUP(datasheet!F15, 'PAGE 1'!$AS$49:$BS$81,26,FALSE),VLOOKUP(datasheet!F15, 'PAGE 1'!$CB$49:$DB$81,26,FALSE)),VLOOKUP(datasheet!F15, 'PAGE 1'!$AS$127:$BS$159,26,FALSE)),VLOOKUP(datasheet!F15, 'PAGE 1'!$CB$127:$DB$159,26,FALSE)),"") -> 23 | K15: 5 | L15: =SUM(G15:K15) -> 28 | O15: Culture | P15: =IFERROR(VLOOKUP(datasheet!O15,'PAGE 1'!$AS$88:$BS$120,26,FALSE),"") | U15: =SUM(P15:T15) -> 0
B16: points left | C16: =C17-C15 -> -5 | F16: Endurance | G16: =IFERROR(IFERROR(IFERROR(IFERROR(VLOOKUP(datasheet!F16, 'PAGE 1'!$AS$49:$BS$81,26,FALSE),VLOOKUP(datasheet!F16, 'PAGE 1'!$CB$49:$DB$81,26,FALSE)),VLOOKUP(datasheet!F16, 'PAGE 1'!$AS$127:$BS$159,26,FALSE)),VLOOKUP(datasheet!F16, 'PAGE 1'!$CB$127:$DB$159,26,FALSE)),"") -> 26 | K16: 22 | L16: =SUM(G16:K16) -> 48 | O16: Disguise | P16: =IFERROR(VLOOKUP(datasheet!O16,'PAGE 1'!$AS$88:$BS$120,26,FALSE),"") | U16: =SUM(P16:T16) -> 0
B17: points allowed | C17: 75 | F17: Evade | G17: =IFERROR(IFERROR(IFERROR(IFERROR(VLOOKUP(datasheet!F17, 'PAGE 1'!$AS$49:$BS$81,26,FALSE),VLOOKUP(datasheet!F17, 'PAGE 1'!$CB$49:$DB$81,26,FALSE)),VLOOKUP(datasheet!F17, 'PAGE 1'!$AS$127:$BS$159,26,FALSE)),VLOOKUP(datasheet!F17, 'PAGE 1'!$CB$127:$DB$159,26,FALSE)),"") -> 32 | K17: 25 | L17: =SUM(G17:K17) -> 57 | O17: Engineering | P17: =IFERROR(VLOOKUP(datasheet!O17,'PAGE 1'!$AS$88:$BS$120,26,FALSE),"") | U17: =SUM(P17:T17) -> 0
F18: First aid | G18: =IFERROR(IFERROR(IFERROR(IFERROR(VLOOKUP(datasheet!F18, 'PAGE 1'!$AS$49:$BS$81,26,FALSE),VLOOKUP(datasheet!F18, 'PAGE 1'!$CB$49:$DB$81,26,FALSE)),VLOOKUP(datasheet!F18, 'PAGE 1'!$AS$127:$BS$159,26,FALSE)),VLOOKUP(datasheet!F18, 'PAGE 1'!$CB$127:$DB$159,26,FALSE)),"") -> 30 | K18: 7 | L18: =SUM(G18:K18) -> 37 | O18: Fly | P18: =IFERROR(VLOOKUP(datasheet!O18,'PAGE 1'!$AS$88:$BS$120,26,FALSE),"") | U18: =SUM(P18:T18) -> 0
B19: Attributes | F19: Influence | G19: =IFERROR(IFERROR(IFERROR(IFERROR(VLOOKUP(datasheet!F19, 'PAGE 1'!$AS$49:$BS$81,26,FALSE),VLOOKUP(datasheet!F19, 'PAGE 1'!$CB$49:$DB$81,26,FALSE)),VLOOKUP(datasheet!F19, 'PAGE 1'!$AS$127:$BS$159,26,FALSE)),VLOOKUP(datasheet!F19, 'PAGE 1'!$CB$127:$DB$159,26,FALSE)),"") -> 18 | K19: 13 | L19: =SUM(G19:K19) -> 31 | O19: Gambling | P19: =IFERROR(VLOOKUP(datasheet!O19,'PAGE 1'!$AS$88:$BS$120,26,FALSE),"") | U19: =SUM(P19:T19) -> 0
B20: AP | C20: =ROUNDUP((C11+C12)/12,0) -> 3 | D20: INT+DEX | F20: Insight | G20: =IFERROR(IFERROR(IFERROR(IFERROR(VLOOKUP(datasheet!F20, 'PAGE 1'!$AS$49:$BS$81,26,FALSE),VLOOKUP(datasheet!F20, 'PAGE 1'!$CB$49:$DB$81,26,FALSE)),VLOOKUP(datasheet!F20, 'PAGE 1'!$AS$127:$BS$159,26,FALSE)),VLOOKUP(datasheet!F20, 'PAGE 1'!$CB$127:$DB$159,26,FALSE)),"") -> 21 | K20: 14 | L20: =SUM(G20:K20) -> 35 | O20: Healing | P20: =IFERROR(VLOOKUP(datasheet!O20,'PAGE 1'!$AS$88:$BS$120,26,FALSE),"") | U20: =SUM(P20:T20) -> 0
B21: Exp Mod | C21: =ROUNDUP(C14/6,0)-2 -> 0 | D21: CHA | F21: Locale | G21: =IFERROR(IFERROR(IFERROR(IFERROR(VLOOKUP(datasheet!F21, 'PAGE 1'!$AS$49:$BS$81,26,FALSE),VLOOKUP(datasheet!F21, 'PAGE 1'!$CB$49:$DB$81,26,FALSE)),VLOOKUP(datasheet!F21, 'PAGE 1'!$AS$127:$BS$159,26,FALSE)),VLOOKUP(datasheet!F21, 'PAGE 1'!$CB$127:$DB$159,26,FALSE)),"") -> 28 | K21: 7 | L21: =SUM(G21:K21) -> 35 | O21: Literacy | P21: =IFERROR(VLOOKUP(datasheet!O21,'PAGE 1'!$AS$88:$BS$120,26,FALSE),"") | U21: =SUM(P21:T21) -> 0
B22: Healing Rate | C22: =ROUNDUP(C9/6,0) -> 3 | D22: CON | F22: Native tongue (Meerish) | G22: =IFERROR(IFERROR(IFERROR(IFERROR(VLOOKUP(datasheet!F22, 'PAGE 1'!$AS$49:$BS$81,26,FALSE),VLOOKUP(datasheet!F22, 'PAGE 1'!$CB$49:$DB$81,26,FALSE)),VLOOKUP(datasheet!F22, 'PAGE 1'!$AS$127:$BS$159,26,FALSE)),VLOOKUP(datasheet!F22, 'PAGE 1'!$CB$127:$DB$159,26,FALSE)),"") -> 23 | K22: 47 | L22: =SUM(G22:K22) -> 70 | O22: Lockpicking | P22: =IFERROR(VLOOKUP(datasheet!O22,'PAGE 1'!$AS$88:$BS$120,26,FALSE),"") | U22: =SUM(P22:T22) -> 0
B23: Luck Points | C23: =ROUNDUP(C13/6,0) -> 2 | D23: POW | F23: Perception | G23: =IFERROR(IFERROR(IFERROR(IFERROR(VLOOKUP(datasheet!F23, 'PAGE 1'!$AS$49:$BS$81,26,FALSE),VLOOKUP(datasheet!F23, 'PAGE 1'!$CB$49:$DB$81,26,FALSE)),VLOOKUP(datasheet!F23, 'PAGE 1'!$AS$127:$BS$159,26,FALSE)),VLOOKUP(datasheet!F23, 'PAGE 1'!$CB$127:$DB$159,26,FALSE)),"") -> 21 | K23: 7 | L23: =SUM(G23:K23) -> 28 | O23: Lore (Geography) | P23: =IFERROR(VLOOKUP(datasheet!O23,'PAGE 1'!$AS$88:$BS$120,26,FALSE),"") -> 28 | T23: 10 | U23: =SUM(P23:T23) -> 38
B24: Magic Points | C24: =C13 -> 7 | D24: POW | F24: Ride | G24: =IFERROR(IFERROR(IFERROR(IFERROR(VLOOKUP(datasheet!F24, 'PAGE 1'!$AS$49:$BS$81,26,FALSE),VLOOKUP(datasheet!F24, 'PAGE 1'!$CB$49:$DB$81,26,FALSE)),VLOOKUP(datasheet!F24, 'PAGE 1'!$AS$127:$BS$159,26,FALSE)),VLOOKUP(datasheet!F24, 'PAGE 1'!$CB$127:$DB$159,26,FALSE)),"") -> 23 | K24: 6 | L24: =SUM(G24:K24) -> 29 | O24: Mechanisms | P24: =IFERROR(VLOOKUP(datasheet!O24,'PAGE 1'!$AS$88:$BS$120,26,FALSE),"") | U24: =SUM(P24:T24) -> 0
B25: Init Bonus | C25: =ROUNDUP(AVERAGE(C12,C11),0) -> 15 | D25: DEX+INT | F25: Sing | G25: =IFERROR(IFERROR(IFERROR(IFERROR(VLOOKUP(datasheet!F25, 'PAGE 1'!$AS$49:$BS$81,26,FALSE),VLOOKUP(datasheet!F25, 'PAGE 1'!$CB$49:$DB$81,26,FALSE)),VLOOKUP(datasheet!F25, 'PAGE 1'!$AS$127:$BS$159,26,FALSE)),VLOOKUP(datasheet!F25, 'PAGE 1'!$CB$127:$DB$159,26,FALSE)),"") -> 16 | L25: =SUM(G25:K25) -> 16 | O25: Musicianship | P25: =IFERROR(VLOOKUP(datasheet!O25,'PAGE 1'!$AS$88:$BS$120,26,FALSE),"") | U25: =SUM(P25:T25) -> 0
B26: Damage Mod | C26: =VLOOKUP(CEILING((C8+C10)/5,1),calculations!A8:B27,2) -> 0 | D26: STR+SIZ | F26: Stealth | G26: =IFERROR(IFERROR(IFERROR(IFERROR(VLOOKUP(datasheet!F26, 'PAGE 1'!$AS$49:$BS$81,26,FALSE),VLOOKUP(datasheet!F26, 'PAGE 1'!$CB$49:$DB$81,26,FALSE)),VLOOKUP(datasheet!F26, 'PAGE 1'!$AS$127:$BS$159,26,FALSE)),VLOOKUP(datasheet!F26, 'PAGE 1'!$CB$127:$DB$159,26,FALSE)),"") -> 30 | L26: =SUM(G26:K26) -> 30 | O26: Navigation () | P26: =IFERROR(VLOOKUP(datasheet!O26,'PAGE 1'!$AS$88:$BS$120,26,FALSE),"") | U26: =SUM(P26:T26) -> 0
F27: Swim | G27: =IFERROR(IFERROR(IFERROR(IFERROR(VLOOKUP(datasheet!F27, 'PAGE 1'!$AS$49:$BS$81,26,FALSE),VLOOKUP(datasheet!F27, 'PAGE 1'!$CB$49:$DB$81,26,FALSE)),VLOOKUP(datasheet!F27, 'PAGE 1'!$AS$127:$BS$159,26,FALSE)),VLOOKUP(datasheet!F27, 'PAGE 1'!$CB$127:$DB$159,26,FALSE)),"") -> 24 | L27: =SUM(G27:K27) -> 24 | O27: Oratory | P27: =IFERROR(VLOOKUP(datasheet!O27,'PAGE 1'!$AS$88:$BS$120,26,FALSE),"") | U27: =SUM(P27:T27) -> 0
B28: HP Per Location | C28: standard | F28: Unarmed | G28: =IFERROR(IFERROR(IFERROR(IFERROR(VLOOKUP(datasheet!F28, 'PAGE 1'!$AS$49:$BS$81,26,FALSE),VLOOKUP(datasheet!F28, 'PAGE 1'!$CB$49:$DB$81,26,FALSE)),VLOOKUP(datasheet!F28, 'PAGE 1'!$AS$127:$BS$159,26,FALSE)),VLOOKUP(datasheet!F28, 'PAGE 1'!$CB$127:$DB$159,26,FALSE)),"") -> 27 | K28: 12 | L28: =SUM(G28:K28) -> 39 | O28: Seamanship | P28: =IFERROR(VLOOKUP(datasheet!O28,'PAGE 1'!$AS$88:$BS$120,26,FALSE),"") | U28: =SUM(P28:T28) -> 0
B29: Head | C29: =ROUNDUP(((C9+C10)/5),0) -> 5 | F29: Willpower | G29: =IFERROR(IFERROR(IFERROR(IFERROR(VLOOKUP(datasheet!F29, 'PAGE 1'!$AS$49:$BS$81,26,FALSE),VLOOKUP(datasheet!F29, 'PAGE 1'!$CB$49:$DB$81,26,FALSE)),VLOOKUP(datasheet!F29, 'PAGE 1'!$AS$127:$BS$159,26,FALSE)),VLOOKUP(datasheet!F29, 'PAGE 1'!$CB$127:$DB$159,26,FALSE)),"") -> 14 | K29: 35 | L29: =SUM(G29:K29) -> 49 | O29: Seduction | P29: =IFERROR(VLOOKUP(datasheet!O29,'PAGE 1'!$AS$88:$BS$120,26,FALSE),"") | U29: =SUM(P29:T29) -> 0
B30: Chest | C30: =ROUNDUP(((C9+C10)/5),0)+2 -> 7 | F30: Meerish Slinger | G30: =IFERROR(IFERROR(IFERROR(IFERROR(VLOOKUP(datasheet!F30, 'PAGE 1'!$AS$49:$BS$81,26,FALSE),VLOOKUP(datasheet!F30, 'PAGE 1'!$CB$49:$DB$81,26,FALSE)),VLOOKUP(datasheet!F30, 'PAGE 1'!$AS$127:$BS$159,26,FALSE)),VLOOKUP(datasheet!F30, 'PAGE 1'!$CB$127:$DB$159,26,FALSE)),"") -> 27 | K30: 50 | L30: =SUM(G30:K30) -> 77 | O30: Sleight | P30: =IFERROR(VLOOKUP(datasheet!O30,'PAGE 1'!$AS$88:$BS$120,26,FALSE),"") | U30: =SUM(P30:T30) -> 0
B31: Abdomen | C31: =ROUNDUP(((C9+C10)/5),0)+1 -> 6 | F31: Custom Skill | G31: =IFERROR(IFERROR(IFERROR(IFERROR(VLOOKUP(datasheet!F31, 'PAGE 1'!$AS$49:$BS$81,26,FALSE),VLOOKUP(datasheet!F31, 'PAGE 1'!$CB$49:$DB$81,26,FALSE)),VLOOKUP(datasheet!F31, 'PAGE 1'!$AS$127:$BS$159,26,FALSE)),VLOOKUP(datasheet!F31, 'PAGE 1'!$CB$127:$DB$159,26,FALSE)),"") | L31: =SUM(G31:K31) -> 0 | O31: Streetwise | P31: =IFERROR(VLOOKUP(datasheet!O31,'PAGE 1'!$AS$88:$BS$120,26,FALSE),"") | U31: =SUM(P31:T31) -> 0
B32: Arm | C32: =MAX(ROUNDUP(((C9+C10)/5),0)-1,1) -> 4 | F32: Passions | O32: Survival | P32: =IFERROR(VLOOKUP(datasheet!O32,'PAGE 1'!$AS$88:$BS$120,26,FALSE),"") -> 20 | T32: 19 | U32: =SUM(P32:T32) -> 39
B33: Leg | C33: =ROUNDUP(((C9+C10)/5),0) -> 5 | F33: skills | J33: base | K33: other | L33: total | O33: Teach | P33: =IFERROR(VLOOKUP(datasheet!O33,'PAGE 1'!$AS$88:$BS$120,26,FALSE),"") | U33: =SUM(P33:T33) -> 0
F34: Hate Cruelty | J34: =IFERROR(IFERROR(IFERROR(VLOOKUP(F34,'PAGE 1'!$AS$166:$BS$183,26,FALSE),VLOOKUP(F34,'PAGE 1'!$CB$166:$DB$183,26,FALSE)),VLOOKUP(F34, 'PAGE 1'!$AS$127:$BS$159,26,FALSE)),"") -> 51 | K34: 24 | L34: =J34+K34 -> 75 | O34: Track | P34: =IFERROR(VLOOKUP(datasheet!O34,'PAGE 1'!$AS$88:$BS$120,26,FALSE),"") | U34: =SUM(P34:T34) -> 0
B35: Character Limits | F35: Love Kara | J35: =IFERROR(IFERROR(IFERROR(VLOOKUP(F35,'PAGE 1'!$AS$166:$BS$183,26,FALSE),VLOOKUP(F35,'PAGE 1'!$CB$166:$DB$183,26,FALSE)),VLOOKUP(F35, 'PAGE 1'!$AS$127:$BS$159,26,FALSE)),"") -> 46 | K35: 60 | L35: =J35+K35 -> 106 | O35: Lore (Military History) | P35: =IFERROR(VLOOKUP(datasheet!O35,'PAGE 1'!$AS$88:$BS$120,26,FALSE),"") -> 28 | T35: 10 | U35: =SUM(P35:T35) -> 38
B36: Age | C36: =G2 -> 28 | D36: =VLOOKUP(C36,calculations!N146:R224,2,"") -> Middle Aged | F36: Loyalty to Meeros | J36: =IFERROR(IFERROR(IFERROR(VLOOKUP(F36,'PAGE 1'!$AS$166:$BS$183,26,FALSE),VLOOKUP(F36,'PAGE 1'!$CB$166:$DB$183,26,FALSE)),VLOOKUP(F36, 'PAGE 1'!$AS$127:$BS$159,26,FALSE)),"") -> 51 | K36: 29 | L36: =J36+K36 -> 80 | O36: Lore (Strategy & Tactics) | P36: =IFERROR(VLOOKUP(datasheet!O36,'PAGE 1'!$AS$88:$BS$120,26,FALSE),"") -> 28 | T36: 10 | U36: =SUM(P36:T36) -> 38
B37: Culture Points | C37: =SUM(H8:H31,H49:H59,Q8:Q40,Q43:Q52,Q56:Q65) -> 0 | D37: 100 | F37: Hate Xenos/Mysoginestes | J37: =IFERROR(IFERROR(IFERROR(VLOOKUP(F37,'PAGE 1'!$AS$166:$BS$183,26,FALSE),VLOOKUP(F37,'PAGE 1'!$CB$166:$DB$183,26,FALSE)),VLOOKUP(F37, 'PAGE 1'!$AS$127:$BS$159,26,FALSE)),"") -> 46 | K37: 44 | L37: =J37+K37 -> 90 | O37: Custom Skill 3 | P37: =IFERROR(VLOOKUP(datasheet!O37,'PAGE 1'!$AS$88:$BS$120,26,FALSE),"") | U37: =SUM(P37:T37) -> 0
B38: Career Points | C38: =SUM(I8:I31,I49:I59,R8:R40,R43:R52,R56:R65) -> 0 | D38: 100 | F38: Respect Zamothis | J38: =IFERROR(IFERROR(IFERROR(VLOOKUP(F38,'PAGE 1'!$AS$166:$BS$183,26,FALSE),VLOOKUP(F38,'PAGE 1'!$CB$166:$DB$183,26,FALSE)),VLOOKUP(F38, 'PAGE 1'!$AS$127:$BS$159,26,FALSE)),"") -> 46 | K38: 34 | L38: =J38+K38 -> 80 | O38: Custom Skill 4 | P38: =IFERROR(VLOOKUP(datasheet!O38,'PAGE 1'!$AS$88:$BS$120,26,FALSE),"") | U38: =SUM(P38:T38) -> 0
B39: Bonus Points | C39: =SUM(J8:J30,J49:J59,S8:S40,S43:S52,S56:S65) -> 0 | D39: =VLOOKUP(C36,calculations!N146:R224,3,"") -> 200 | F39: Passion 6 | J39: =IFERROR(IFERROR(IFERROR(VLOOKUP(F39,'PAGE 1'!$AS$166:$BS$183,26,FALSE),VLOOKUP(F39,'PAGE 1'!$CB$166:$DB$183,26,FALSE)),VLOOKUP(F39, 'PAGE 1'!$AS$127:$BS$159,26,FALSE)),"") | L39: =J39+K39 -> 0 | O39: Custom Skill 5 | P39: =IFERROR(VLOOKUP(datasheet!O39,'PAGE 1'!$AS$88:$BS$120,26,FALSE),"") | U39: =SUM(P39:T39) -> 0
B40: Bonus Point Limit | D40: =VLOOKUP(C36,calculations!N146:R224,4,"") -> 20 | F40: Passion 7 | J40: =IFERROR(IFERROR(IFERROR(VLOOKUP(F40,'PAGE 1'!$AS$166:$BS$183,26,FALSE),VLOOKUP(F40,'PAGE 1'!$CB$166:$DB$183,26,FALSE)),VLOOKUP(F40, 'PAGE 1'!$AS$127:$BS$159,26,FALSE)),"") | L40: =J40+K40 -> 0 | O40: Custom Skill 6 | P40: =IFERROR(VLOOKUP(datasheet!O40,'PAGE 1'!$AS$88:$BS$120,26,FALSE),"") | U40: =SUM(P40:T40) -> 0
F41: Passion 8 | J41: =IFERROR(IFERROR(IFERROR(VLOOKUP(F41,'PAGE 1'!$AS$166:$BS$183,26,FALSE),VLOOKUP(F41,'PAGE 1'!$CB$166:$DB$183,26,FALSE)),VLOOKUP(F41, 'PAGE 1'!$AS$127:$BS$159,26,FALSE)),"") | L41: =J41+K41 -> 0 | O41: Combat Styles
...

Sheet PAGE 1
AS3: Character Name | BG3: =NAME -> Anathaym
AS5: Player Name | BD5: =datasheet!$C$3 -> Adept_Austin | CB5: Race/Homeland | CP5: =IF(datasheet!$G$3<>"", CONCATENATE(datasheet!$G$3,"/",datasheet!$G$4),"") -> Human/Meeros
AS7: Culture | AZ7: =datasheet!C4 -> Civilised | CB7: Career/Profession | CQ7: =IF(datasheet!$P$3<>"", CONCATENATE(datasheet!$P$2,"/",datasheet!$P$3),"") -> Warrior/Scarlet Spear
AS9: Age | AW9: =CONCATENATE(datasheet!$C$36&", "&datasheet!$D$36) -> 28, Middle Aged | BK9: Gender | BR9: Female | CB9: Social Class | CM9: =datasheet!P4 -> Aristocracy
AS11: Handedness | BD11: Left | BK11: Frame | BQ11: Lithe | CB11: Height | CH11: 165 | CQ11: cm | CT11: Weight | DA11: 47 | DG11: kg
J13: Character Record Sheet | AS13: Description
AS15: Long dark hair, member of the Scarlet Spears, quick temper, but good hearted. Initiate of Myceras The daughter of a famed general of Myceras, Anthaym is following in her father's sandals as a member of the elite Scarlet Spears – one of the royal household companies of Meeros. Anathaym is quick-witted, quick-tempered, and prone to acting before thinking sometimes, but is loyal, brave, kind-hearted and a passionate champion of her home. Her sister is Kara, the priestess of Myceras, and Anathaym has recently been initiated into the cult of War God of Meeros. She is keen to show her devotion to her god, her love for the city, and to protect those who request and require her help. Trimostones is an old family friend and so it is natural for Anathaym to want to travel to Iaxos with him as a bodyguard: she does not care about the rumours and legends of cannibals: she is eager to prove her spear and sword against any who wish to try their luck. Her good friend and mentor is Master Zamothis, the warrior who trained her and taught her everything she knows. She loves her sister dearly, but she loves and admires Master Zamothis as much as she loves and admires her father. Indeed, she listens to Zamothis more than she listens to either her father or Kara. Anathaym knows two Folk Magic spells: Bladesharp and Coordination. She usually casts Bladesharp on her both her weapons if she has time before entering a battle. If time is short, her favoured weapon is her spear and so she tries to cast Bladesharp on that, first.
C17: Character Portrait
AS43: Standard Skills | CC43: Difficulty Mod | CS43: Standard
AS46: Skill | BF46: Base (Stat+Stat+N) | BR46: % | BX46: ⊕ | CB46: Skill | CO46: Base (Stat+Stat+N) | DA46: % | DG46: ⊕
AS49: Athletics | BD49: TRUE | BF49: STR | BK49: DEX | BR49: =IF(AND(ISBLANK(BF49),ISBLANK(BK49),ISBLANK(BP49)),"",(IFERROR(IF(ISBLANK(BF49),0, VLOOKUP(BF49,calculations!$C$8:$D$21,2,0)),BF49)+IFERROR(IF(ISBLANK(BK49),0, VLOOKUP(BK49,calculations!$C$8:$D$21,2,0)),BK49)+BP49)) -> 27 | BT49: FALSE | BV49: FALSE | BX49: =IFERROR(Ceiling(VLOOKUP('PAGE 1'!AS49, datasheet!$F$8:$L$31,7,FALSE)*LOOKUP($CS$43,calculations!$A$63:$A$68,calculations!$B$63:$B$68),1),"") -> 44 | CB49: Influence | CM49: FALSE | CO49: CHA | CT49: CHA | DA49: =IF(AND(ISBLANK(CO49),ISBLANK(CT49),ISBLANK(CY49)),"",(IFERROR(IF(ISBLANK(CO49),0, VLOOKUP(CO49,calculations!$C$8:$D$21,2,0)),CO49)+IFERROR(IF(ISBLANK(CT49),0, VLOOKUP(CT49,calculations!$C$8:$D$21,2,0)),CT49)+CY49)) -> 18 | DC49: FALSE | DE49: FALSE | DG49: =IFERROR(Ceiling(VLOOKUP('PAGE 1'!CB49, datasheet!$F$8:$L$31,7,FALSE)*LOOKUP($CS$43,calculations!$A$63:$A$68,calculations!$B$63:$B$68),1),"") -> 31
AS52: Boating | BD52: TRUE | BF52: STR | BK52: CON | BR52: =IF(AND(ISBLANK(BF52),ISBLANK(BK52),ISBLANK(BP52)),"",(IFERROR(IF(ISBLANK(BF52),0, VLOOKUP(BF52,calculations!$C$8:$D$21,2,0)),BF52)+IFERROR(IF(ISBLANK(BK52),0, VLOOKUP(BK52,calculations!$C$8:$D$21,2,0)),BK52)+BP52)) -> 24 | BT52: FALSE | BV52: FALSE | BX52: =IFERROR(Ceiling(VLOOKUP('PAGE 1'!AS52, datasheet!$F$8:$L$31,7,FALSE)*LOOKUP($CS$43,calculations!$A$63:$A$68,calculations!$B$63:$B$68),1),"") -> 24 | CB52: Insight | CM52: FALSE | CO52: INT | CT52: POW | DA52: =IF(AND(ISBLANK(CO52),ISBLANK(CT52),ISBLANK(CY52)),"",(IFERROR(IF(ISBLANK(CO52),0, VLOOKUP(CO52,calculations!$C$8:$D$21,2,0)),CO52)+IFERROR(IF(ISBLANK(CT52),0, VLOOKUP(CT52,calculations!$C$8:$D$21,2,0)),CT52)+CY52)) -> 21 | DC52: FALSE | DE52: FALSE | DG52: =IFERROR(Ceiling(VLOOKUP('PAGE 1'!CB52, datasheet!$F$8:$L$31,7,FALSE)*LOOKUP($CS$43,calculations!$A$63:$A$68,calculations!$B$63:$B$68),1),"") -> 35
AS55: Brawn | BD55: TRUE | BF55: STR | BK55: SIZ | BR55: =IF(AND(ISBLANK(BF55),ISBLANK(BK55),ISBLANK(BP55)),"",(IFERROR(IF(ISBLANK(BF55),0, VLOOKUP(BF55,calculations!$C$8:$D$21,2,0)),BF55)+IFERROR(IF(ISBLANK(BK55),0, VLOOKUP(BK55,calculations!$C$8:$D$21,2,0)),BK55)+BP55)) -> 21 | BT55: FALSE | BV55: FALSE | BX55: =IFERROR(Ceiling(VLOOKUP('PAGE 1'!AS55, datasheet!$F$8:$L$31,7,FALSE)*LOOKUP($CS$43,calculations!$A$63:$A$68,calculations!$B$63:$B$68),1),"") -> 25 | CB55: Locale | CM55: FALSE | CO55: INT | CT55: INT | DA55: =IF(AND(ISBLANK(CO55),ISBLANK(CT55),ISBLANK(CY55)),"",(IFERROR(IF(ISBLANK(CO55),0, VLOOKUP(CO55,calculations!$C$8:$D$21,2,0)),CO55)+IFERROR(IF(ISBLANK(CT55),0, VLOOKUP(CT55,calculations!$C$8:$D$21,2,0)),CT55)+CY55)) -> 28 | DC55: FALSE | DE55: FALSE | DG55: =IFERROR(Ceiling(VLOOKUP('PAGE 1'!CB55, datasheet!$F$8:$L$31,7,FALSE)*LOOKUP($CS$43,calculations!$A$63:$A$68,calculations!$B$63:$B$68),1),"") -> 35
AS58: Conceal | BD58: TRUE | BF58: DEX | BK58: POW | BR58: =IF(AND(ISBLANK(BF58),ISBLANK(BK58),ISBLANK(BP58)),"",(IFERROR(IF(ISBLANK(BF58),0, VLOOKUP(BF58,calculations!$C$8:$D$21,2,0)),BF58)+IFERROR(IF(ISBLANK(BK58),0, VLOOKUP(BK58,calculations!$C$8:$D$21,2,0)),BK58)+BP58)) -> 23 | BT58: FALSE | BV58: FALSE | BX58: =IFERROR(Ceiling(VLOOKUP('PAGE 1'!AS58, datasheet!$F$8:$L$31,7,FALSE)*LOOKUP($CS$43,calculations!$A$63:$A$68,calculations!$B$63:$B$68),1),"") -> 23 | CB58: Perception | CM58: FALSE | CO58: INT | CT58: POW | DA58: =IF(AND(ISBLANK(CO58),ISBLANK(CT58),ISBLANK(CY58)),"",(IFERROR(IF(ISBLANK(CO58),0, VLOOKUP(CO58,calculations!$C$8:$D$21,2,0)),CO58)+IFERROR(IF(ISBLANK(CT58),0, VLOOKUP(CT58,calculations!$C$8:$D$21,2,0)),CT58)+CY58)) -> 21 | DC58: FALSE | DE58: FALSE | DG58: =IFERROR(Ceiling(VLOOKUP('PAGE 1'!CB58, datasheet!$F$8:$L$31,7,FALSE)*LOOKUP($CS$43,calculations!$A$63:$A$68,calculations!$B$63:$B$68),1),"") -> 28
AS61: Customs (Meeros) | BD61: FALSE | BF61: INT | BK61: INT | BR61: =IF(AND(ISBLANK(BF61),ISBLANK(BK61),ISBLANK(BP61)),"",(IFERROR(IF(ISBLANK(BF61),0, VLOOKUP(BF61,calculations!$C$8:$D$21,2,0)),BF61)+IFERROR(IF(ISBLANK(BK61),0, VLOOKUP(BK61,calculations!$C$8:$D$21,2,0)),BK61)+BP61)) -> 28 | BT61: FALSE | BV61: FALSE | BX61: =IFERROR(Ceiling(VLOOKUP('PAGE 1'!AS61, datasheet!$F$8:$L$31,7,FALSE)*LOOKUP($CS$43,calculations!$A$63:$A$68,calculations!$B$63:$B$68),1),"") -> 74 | CB61: Ride | CM61: TRUE | CO61: DEX | CT61: POW | DA61: =IF(AND(ISBLANK(CO61),ISBLANK(CT61),ISBLANK(CY61)),"",(IFERROR(IF(ISBLANK(CO61),0, VLOOKUP(CO61,calculations!$C$8:$D$21,2,0)),CO61)+IFERROR(IF(ISBLANK(CT61),0, VLOOKUP(CT61,calculations!$C$8:$D$21,2,0)),CT61)+CY61)) -> 23 | DC61: FALSE | DE61: FALSE | DG61: =IFERROR(Ceiling(VLOOKUP('PAGE 1'!CB61, datasheet!$F$8:$L$31,7,FALSE)*LOOKUP($CS$43,calculations!$A$63:$A$68,calculations!$B$63:$B$68),1),"") -> 29
AS64: Dance | BD64: TRUE | BF64: DEX | BK64: CHA | BR64: =IF(AND(ISBLANK(BF64),ISBLANK(BK64),ISBLANK(BP64)),"",(IFERROR(IF(ISBLANK(BF64),0, VLOOKUP(BF64,calculations!$C$8:$D$21,2,0)),BF64)+IFERROR(IF(ISBLANK(BK64),0, VLOOKUP(BK64,calculations!$C$8:$D$21,2,0)),BK64)+BP64)) -> 25 | BT64: FALSE | BV64: FALSE | BX64: =IFERROR(Ceiling(VLOOKUP('PAGE 1'!AS64, datasheet!$F$8:$L$31,7,FALSE)*LOOKUP($CS$43,calculations!$A$63:$A$68,calculations!$B$63:$B$68),1),"") -> 25 | CB64: Sing | CM64: FALSE | CO64: POW | CT64: CHA | DA64: =IF(AND(ISBLANK(CO64),ISBLANK(CT64),ISBLANK(CY64)),"",(IFERROR(IF(ISBLANK(CO64),0, VLOOKUP(CO64,calculations!$C$8:$D$21,2,0)),CO64)+IFERROR(IF(ISBLANK(CT64),0, VLOOKUP(CT64,calculations!$C$8:$D$21,2,0)),CT64)+CY64)) -> 16 | DC64: FALSE | DE64: FALSE | DG64: =IFERROR(Ceiling(VLOOKUP('PAGE 1'!CB64, datasheet!$F$8:$L$31,7,FALSE)*LOOKUP($CS$43,calculations!$A$63:$A$68,calculations!$B$63:$B$68),1),"") -> 16
AS67: Deceit | BD67: FALSE | BF67: INT | BK67: CHA | BR67: =IF(AND(ISBLANK(BF67),ISBLANK(BK67),ISBLANK(BP67)),"",(IFERROR(IF(ISBLANK(BF67),0, VLOOKUP(BF67,calculations!$C$8:$D$21,2,0)),BF67)+IFERROR(IF(ISBLANK(BK67),0, VLOOKUP(BK67,calculations!$C$8:$D$21,2,0)),BK67)+BP67)) -> 23 | BT67: FALSE | BV67: FALSE | BX67: =IFERROR(Ceiling(VLOOKUP('PAGE 1'!AS67, datasheet!$F$8:$L$31,7,FALSE)*LOOKUP($CS$43,calculations!$A$63:$A$68,calculations!$B$63:$B$68),1),"") -> 28 | CB67: Stealth | CM67: TRUE | CO67: DEX | CT67: INT | DA67: =IF(AND(ISBLANK(CO67),ISBLANK(CT67),ISBLANK(CY67)),"",(IFERROR(IF(ISBLANK(CO67),0, VLOOKUP(CO67,calculations!$C$8:$D$21,2,0)),CO67)+IFERROR(IF(ISBLANK(CT67),0, VLOOKUP(CT67,calculations!$C$8:$D$21,2,0)),CT67)+CY67)) -> 30 | DC67: FALSE | DE67: FALSE | DG67: =IFERROR(Ceiling(VLOOKUP('PAGE 1'!CB67, datasheet!$F$8:$L$31,7,FALSE)*LOOKUP($CS$43,calculations!$A$63:$A$68,calculations!$B$63:$B$68),1),"") -> 30
AS70: Drive | BD70: TRUE | BF70: DEX | BK70: POW | BR70: =IF(AND(ISBLANK(BF70),ISBLANK(BK70),ISBLANK(BP70)),"",(IFERROR(IF(ISBLANK(BF70),0, VLOOKUP(BF70,calculations!$C$8:$D$21,2,0)),BF70)+IFERROR(IF(ISBLANK(BK70),0, VLOOKUP(BK70,calculations!$C$8:$D$21,2,0)),BK70)+BP70)) -> 23 | BT70: FALSE | BV70: FALSE | BX70: =IFERROR(Ceiling(VLOOKUP('PAGE 1'!AS70, datasheet!$F$8:$L$31,7,FALSE)*LOOKUP($CS$43,calculations!$A$63:$A$68,calculations!$B$63:$B$68),1),"") -> 28 | CB70: Swim | CM70: TRUE | CO70: STR | CT70: CON | DA70: =IF(AND(ISBLANK(CO70),ISBLANK(CT70),ISBLANK(CY70)),"",(IFERROR(IF(ISBLANK(CO70),0, VLOOKUP(CO70,calculations!$C$8:$D$21,2,0)),CO70)+IFERROR(IF(ISBLANK(CT70),0, VLOOKUP(CT70,calculations!$C$8:$D$21,2,0)),CT70)+CY70)) -> 24 | DC70: FALSE | DE70: FALSE | DG70: =IFERROR(Ceiling(VLOOKUP('PAGE 1'!CB70, datasheet!$F$8:$L$31,7,FALSE)*LOOKUP($CS$43,calculations!$A$63:$A$68,calculations!$B$63:$B$68),1),"") -> 24
C72: Characteristics & Attributes
AS73: Endurance | BD73: FALSE | BF73: CON | BK73: CON | BR73: =IF(AND(ISBLANK(BF73),ISBLANK(BK73),ISBLANK(BP73)),"",(IFERROR(IF(ISBLANK(BF73),0, VLOOKUP(BF73,calculations!$C$8:$D$21,2,0)),BF73)+IFERROR(IF(ISBLANK(BK73),0, VLOOKUP(BK73,calculations!$C$8:$D$21,2,0)),BK73)+BP73)) -> 26 | BT73: FALSE | BV73: FALSE | BX73: =IFERROR(Ceiling(VLOOKUP('PAGE 1'!AS73, datasheet!$F$8:$L$31,7,FALSE)*LOOKUP($CS$43,calculations!$A$63:$A$68,calculations!$B$63:$B$68),1),"") -> 48 | CB73: Unarmed | CM73: TRUE | CO73: STR | CT73: DEX | DA73: =IF(AND(ISBLANK(CO73),ISBLANK(CT73),ISBLANK(CY73)),"",(IFERROR(IF(ISBLANK(CO73),0, VLOOKUP(CO73,calculations!$C$8:$D$21,2,0)),CO73)+IFERROR(IF(ISBLANK(CT73),0, VLOOKUP(CT73,calculations!$C$8:$D$21,2,0)),CT73)+CY73)) -> 27 | DC73: FALSE | DE73: FALSE | DG73: =IFERROR(Ceiling(VLOOKUP('PAGE 1'!CB73, datasheet!$F$8:$L$31,7,FALSE)*LOOKUP($CS$43,calculations!$A$63:$A$68,calculations!$B$63:$B$68),1),"") -> 39
C75: Strength (STR) | T75: =STR+Q75 -> 11 | W75: Action Points | AN75: =ActionPoints+AK75 -> 3
AS76: Evade | BD76: TRUE | BF76: DEX | BK76: DEX | BR76: =IF(AND(ISBLANK(BF76),ISBLANK(BK76),ISBLANK(BP76)),"",(IFERROR(IF(ISBLANK(BF76),0, VLOOKUP(BF76,calculations!$C$8:$D$21,2,0)),BF76)+IFERROR(IF(ISBLANK(BK76),0, VLOOKUP(BK76,calculations!$C$8:$D$21,2,0)),BK76)+BP76)) -> 32 | BT76: FALSE | BV76: FALSE | BX76: =IFERROR(Ceiling(VLOOKUP('PAGE 1'!AS76, datasheet!$F$8:$L$31,7,FALSE)*LOOKUP($CS$43,calculations!$A$63:$A$68,calculations!$B$63:$B$68),1),"") -> 57 | CB76: Willpower | CM76: FALSE | CO76: POW | CT76: POW | DA76: =IF(AND(ISBLANK(CO76),ISBLANK(CT76),ISBLANK(CY76)),"",(IFERROR(IF(ISBLANK(CO76),0, VLOOKUP(CO76,calculations!$C$8:$D$21,2,0)),CO76)+IFERROR(IF(ISBLANK(CT76),0, VLOOKUP(CT76,calculations!$C$8:$D$21,2,0)),CT76)+CY76)) -> 14 | DC76: FALSE | DE76: FALSE | DG76: =IFERROR(Ceiling(VLOOKUP('PAGE 1'!CB76, datasheet!$F$8:$L$31,7,FALSE)*LOOKUP($CS$43,calculations!$A$63:$A$68,calculations!$B$63:$B$68),1),"") -> 49
C79: Constitution (CON) | T79: =CON+Q79 -> 13 | W79: Damage Modifier | AN79: =IFERROR(VLOOKUP(CEILING((datasheet!C8+datasheet!C10)/5+AK79,1),calculations!A8:B27,2),DamageMod) -> 0 | AS79: First Aid | BD79: TRUE | BF79: DEX | BK79: INT | BR79: =IF(AND(ISBLANK(BF79),ISBLANK(BK79),ISBLANK(BP79)),"",(IFERROR(IF(ISBLANK(BF79),0, VLOOKUP(BF79,calculations!$C$8:$D$21,2,0)),BF79)+IFERROR(IF(ISBLANK(BK79),0, VLOOKUP(BK79,calculations!$C$8:$D$21,2,0)),BK79)+BP79)) -> 30 | BT79: FALSE | BV79: FALSE | BX79: =IFERROR(Ceiling(VLOOKUP('PAGE 1'!AS79, datasheet!$F$8:$L$31,7,FALSE)*LOOKUP($CS$43,calculations!$A$63:$A$68,calculations!$B$63:$B$68),1),"") -> 37 | CM79: FALSE | DA79: =IF(AND(ISBLANK(CO79),ISBLANK(CT79),ISBLANK(CY79)),"",(IFERROR(IF(ISBLANK(CO79),0, VLOOKUP(CO79,calculations!$C$8:$D$21,2,0)),CO79)+IFERROR(IF(ISBLANK(CT79),0, VLOOKUP(CT79,calculations!$C$8:$D$21,2,0)),CT79)+CY79)) | DC79: FALSE | DE79: FALSE | DG79: =IFERROR(Ceiling(VLOOKUP('PAGE 1'!CB79, datasheet!$F$8:$L$31,7,FALSE)*LOOKUP($CS$43,calculations!$A$63:$A$68,calculations!$B$63:$B$68),1),"")
AS82: Professional Skills | CB82: Magic Skills
C83: Size (SIZ) | T83: =SIZ+Q83 -> 10 | W83: EXP Modifier | AN83: =ExpModifier+AK83 -> 0
AS85: Skill | BF85: Base (Stat+Stat+N) | BR85: % | BX85: ⊕ | CB85: Skill | CO85: Base (Stat+Stat+N) | DA85: % | DG85: ⊕
C87: Dexterity (DEX) | T87: =DEX+Q87 -> 16 | W87: Healing Rate | AN87: =HealingRate+AK87 -> 3
AS88: Courtesy | BD88: FALSE | BF88: INT | BK88: CHA | BR88: =IF(AND(ISBLANK(BF88),ISBLANK(BK88),ISBLANK(BP88)),"",(IFERROR(IF(ISBLANK(BF88),0, VLOOKUP(BF88,calculations!$C$8:$D$21,2,0)),BF88)+IFERROR(IF(ISBLANK(BK88),0, VLOOKUP(BK88,calculations!$C$8:$D$21,2,0)),BK88)+BP88)) -> 23 | BT88: TRUE | BV88: FALSE | BX88: =IFERROR(Ceiling(VLOOKUP('PAGE 1'!AS88,datasheet!$O$8:$U$40,7,FALSE)*LOOKUP($CS$43,calculations!$A$63:$A$68,calculations!$B$63:$B$68),1),"") -> 38 | CB88: Folk Magic | CM88: FALSE | CO88: POW | CT88: CHA | DA88: =IF(AND(ISBLANK(CO88),ISBLANK(CT88),ISBLANK(CY88)),"",(IFERROR(IF(ISBLANK(CO88),0, VLOOKUP(CO88,calculations!$C$8:$D$21,2,0)),CO88)+IFERROR(IF(ISBLANK(CT88),0, VLOOKUP(CT88,calculations!$C$8:$D$21,2,0)),CT88)+CY88)) -> 16 | DC88: FALSE | DE88: FALSE | DG88: =IFERROR(Ceiling(VLOOKUP('PAGE 1'!CB88,datasheet!$F$49:$L$59,7,FALSE)*LOOKUP($CS$43,calculations!$A$63:$A$68,calculations!$B$63:$B$68),1),"") -> 38
C91: Intelligence (INT) | T91: =INT+Q91 -> 14 | W91: Initiative Bonus | AK91: =-'PAGE 2'!DF26 -> -5 | AN91: =InitBonus+AK91 -> 10 | AS91: Lore (Geography) | BD91: FALSE | BF91: INT | BK91: INT | BR91: =IF(AND(ISBLANK(BF91),ISBLANK(BK91),ISBLANK(BP91)),"",(IFERROR(IF(ISBLANK(BF91),0, VLOOKUP(BF91,calculations!$C$8:$D$21,2,0)),BF91)+IFERROR(IF(ISBLANK(BK91),0, VLOOKUP(BK91,calculations!$C$8:$D$21,2,0)),BK91)+BP91)) -> 28 | BT91: FALSE | BV91: FALSE | BX91: =IFERROR(Ceiling(VLOOKUP('PAGE 1'!AS91,datasheet!$O$8:$U$40,7,FALSE)*LOOKUP($CS$43,calculations!$A$63:$A$68,calculations!$B$63:$B$68),1),"") -> 38 | CM91: FALSE | DA91: =IF(AND(ISBLANK(CO91),ISBLANK(CT91),ISBLANK(CY91)),"",(IFERROR(IF(ISBLANK(CO91),0, VLOOKUP(CO91,calculations!$C$8:$D$21,2,0)),CO91)+IFERROR(IF(ISBLANK(CT91),0, VLOOKUP(CT91,calculations!$C$8:$D$21,2,0)),CT91)+CY91)) | DC91: FALSE | DE91: FALSE | DG91: =IFERROR(Ceiling(VLOOKUP('PAGE 1'!CB91,datasheet!$F$49:$L$59,7,FALSE)*LOOKUP($CS$43,calculations!$A$63:$A$68,calculations!$B$63:$B$68),1),"")
AS94: Lore (Military History) | BD94: FALSE | BF94: INT | BK94: INT | BR94: =IF(AND(ISBLANK(BF94),ISBLANK(BK94),ISBLANK(BP94)),"",(IFERROR(IF(ISBLANK(BF94),0, VLOOKUP(BF94,calculations!$C$8:$D$21,2,0)),BF94)+IFERROR(IF(ISBLANK(BK94),0, VLOOKUP(BK94,calculations!$C$8:$D$21,2,0)),BK94)+BP94)) -> 28 | BT94: FALSE | BV94: FALSE | BX94: =IFERROR(Ceiling(VLOOKUP('PAGE 1'!AS94,datasheet!$O$8:$U$40,7,FALSE)*LOOKUP($CS$43,calculations!$A$63:$A$68,calculations!$B$63:$B$68),1),"") -> 38 | CM94: FALSE | DA94: =IF(AND(ISBLANK(CO94),ISBLANK(CT94),ISBLANK(CY94)),"",(IFERROR(IF(ISBLANK(CO94),0, VLOOKUP(CO94,calculations!$C$8:$D$21,2,0)),CO94)+IFERROR(IF(ISBLANK(CT94),0, VLOOKUP(CT94,calculations!$C$8:$D$21,2,0)),CT94)+CY94)) | DC94: FALSE | DE94: FALSE | DG94: =IFERROR(Ceiling(VLOOKUP('PAGE 1'!CB94,datasheet!$F$49:$L$59,7,FALSE)*LOOKUP($CS$43,calculations!$A$63:$A$68,calculations!$B$63:$B$68),1),"")
C95: Power (POW) | T95: =POW+Q95 -> 7 | W95: Luck Points | AN95: =LuckPoints+AK95 -> 2
AS97: Lore (Strategy & Tactics) | BD97: FALSE | BF97: INT | BK97: INT | BR97: =IF(AND(ISBLANK(BF97),ISBLANK(BK97),ISBLANK(BP97)),"",(IFERROR(IF(ISBLANK(BF97),0, VLOOKUP(BF97,calculations!$C$8:$D$21,2,0)),BF97)+IFERROR(IF(ISBLANK(BK97),0, VLOOKUP(BK97,calculations!$C$8:$D$21,2,0)),BK97)+BP97)) -> 28 | BT97: FALSE | BV97: FALSE | BX97: =IFERROR(Ceiling(VLOOKUP('PAGE 1'!AS97, datasheet!$O$8:$U$40,7,FALSE)*LOOKUP($CS$43,calculations!$A$63:$A$68,calculations!$B$63:$B$68),1),"") -> 38 | CM97: FALSE | DA97: =IF(AND(ISBLANK(CO97),ISBLANK(CT97),ISBLANK(CY97)),"",(IFERROR(IF(ISBLANK(CO97),0, VLOOKUP(CO97,calculations!$C$8:$D$21,2,0)),CO97)+IFERROR(IF(ISBLANK(CT97),0, VLOOKUP(CT97,calculations!$C$8:$D$21,2,0)),CT97)+CY97)) | DC97: FALSE | DE97: FALSE | DG97: =IFERROR(Ceiling(VLOOKUP('PAGE 1'!CB97,datasheet!$F$49:$L$59,7,FALSE)*LOOKUP($CS$43,calculations!$A$63:$A$68,calculations!$B$63:$B$68),1),"")
C99: Charisma (CHA) | T99: =CHA+Q99 -> 9 | W99: Movement Rate | AN99: =6+AK99 -> 6
AS100: Survival | BD100: FALSE | BF100: CON | BK100: POW | BR100: =IF(AND(ISBLANK(BF100),ISBLANK(BK100),ISBLANK(BP100)),"",(IFERROR(IF(ISBLANK(BF100),0, VLOOKUP(BF100,calculations!$C$8:$D$21,2,0)),BF100)+IFERROR(IF(ISBLANK(BK100),0, VLOOKUP(BK100,calculations!$C$8:$D$21,2,0)),BK100)+BP100)) -> 20 | BT100: FALSE | BV100: FALSE | BX100: =IFERROR(Ceiling(VLOOKUP('PAGE 1'!AS100, datasheet!$O$8:$U$40,7,FALSE)*LOOKUP($CS$43,calculations!$A$63:$A$68,calculations!$B$63:$B$68),1),"") -> 39 | CM100: FALSE | DA100: =IF(AND(ISBLANK(CO100),ISBLANK(CT100),ISBLANK(CY100)),"",(IFERROR(IF(ISBLANK(CO100),0, VLOOKUP(CO100,calculations!$C$8:$D$21,2,0)),CO100)+IFERROR(IF(ISBLANK(CT100),0, VLOOKUP(CT100,calculations!$C$8:$D$21,2,0)),CT100)+CY100)) | DC100: FALSE | DE100: FALSE | DG100: =IFERROR(Ceiling(VLOOKUP('PAGE 1'!CB100,datasheet!$F$49:$L$59,7,FALSE)*LOOKUP($CS$43,calculations!$A$63:$A$68,calculations!$B$63:$B$68),1),"")
W103: Tenacity | AN103: =CURRENT_POW+AK103 -> 7 | BD103: FALSE | BR103: =IF(AND(ISBLANK(BF103),ISBLANK(BK103),ISBLANK(BP103)),"",(IFERROR(IF(ISBLANK(BF103),0, VLOOKUP(BF103,calculations!$C$8:$D$21,2,0)),BF103)+IFERROR(IF(ISBLANK(BK103),0, VLOOKUP(BK103,calculations!$C$8:$D$21,2,0)),BK103)+BP103)) | BT103: FALSE | BV103: FALSE | BX103: =IFERROR(Ceiling(VLOOKUP('PAGE 1'!AS103, datasheet!$O$8:$U$40,7,FALSE)*LOOKUP($CS$43,calculations!$A$63:$A$68,calculations!$B$63:$B$68),1),"") | CM103: FALSE | DA103: =IF(AND(ISBLANK(CO103),ISBLANK(CT103),ISBLANK(CY103)),"",(IFERROR(IF(ISBLANK(CO103),0, VLOOKUP(CO103,calculations!$C$8:$D$21,2,0)),CO103)+IFERROR(IF(ISBLANK(CT103),0, VLOOKUP(CT103,calculations!$C$8:$D$21,2,0)),CT103)+CY103)) | DC103: FALSE | DE103: FALSE | DG103: =IFERROR(Ceiling(VLOOKUP('PAGE 1'!CB103,datasheet!$F$49:$L$59,7,FALSE)*LOOKUP($CS$43,calculations!$A$63:$A$68,calculations!$B$63:$B$68),1),"")
BD106: FALSE | BR106: =IF(AND(ISBLANK(BF106),ISBLANK(BK106),ISBLANK(BP106)),"",(IFERROR(IF(ISBLANK(BF106),0, VLOOKUP(BF106,calculations!$C$8:$D$21,2,0)),BF106)+IFERROR(IF(ISBLANK(BK106),0, VLOOKUP(BK106,calculations!$C$8:$D$21,2,0)),BK106)+BP106)) | BT106: FALSE | BV106: FALSE | BX106: =IFERROR(Ceiling(VLOOKUP('PAGE 1'!AS106, datasheet!$O$8:$U$40,7,FALSE)*LOOKUP($CS$43,calculations!$A$63:$A$68,calculations!$B$63:$B$68),1),"") | CM106: FALSE | DA106: =IF(AND(ISBLANK(CO106),ISBLANK(CT106),ISBLANK(CY106)),"",(IFERROR(IF(ISBLANK(CO106),0, VLOOKUP(CO106,calculations!$C$8:$D$21,2,0)),CO106)+IFERROR(IF(ISBLANK(CT106),0, VLOOKUP(CT106,calculations!$C$8:$D$21,2,0)),CT106)+CY106)) | DC106: FALSE | DE106: FALSE | DG106: =IFERROR(Ceiling(VLOOKUP('PAGE 1'!CB106,datasheet!$F$49:$L$59,7,FALSE)*LOOKUP($CS$43,calculations!$A$63:$A$68,calculations!$B$63:$B$68),1),"")
C109: Magic Points | BD109: FALSE | BR109: =IF(AND(ISBLANK(BF109),ISBLANK(BK109),ISBLANK(BP109)),"",(IFERROR(IF(ISBLANK(BF109),0, VLOOKUP(BF109,calculations!$C$8:$D$21,2,0)),BF109)+IFERROR(IF(ISBLANK(BK109),0, VLOOKUP(BK109,calculations!$C$8:$D$21,2,0)),BK109)+BP109)) | BT109: FALSE | BV109: FALSE | BX109: =IFERROR(Ceiling(VLOOKUP('PAGE 1'!AS109, datasheet!$O$8:$U$40,7,FALSE)*LOOKUP($CS$43,calculations!$A$63:$A$68,calculations!$B$63:$B$68),1),"") | CM109: FALSE | DA109: =IF(AND(ISBLANK(CO109),ISBLANK(CT109),ISBLANK(CY109)),"",(IFERROR(IF(ISBLANK(CO109),0, VLOOKUP(CO109,calculations!$C$8:$D$21,2,0)),CO109)+IFERROR(IF(ISBLANK(CT109),0, VLOOKUP(CT109,calculations!$C$8:$D$21,2,0)),CT109)+CY109)) | DC109: FALSE | DE109: FALSE | DG109: =IFERROR(Ceiling(VLOOKUP('PAGE 1'!CB109,datasheet!$F$49:$L$59,7,FALSE)*LOOKUP($CS$43,calculations!$A$63:$A$68,calculations!$B$63:$B$68),1),"")
C112: POW | I112: =T95 -> 7 | O112: Temp | AA112: Total | AJ112: =I112+U112 -> 7 | BD112: FALSE | BR112: =IF(AND(ISBLANK(BF112),ISBLANK(BK112),ISBLANK(BP112)),"",(IFERROR(IF(ISBLANK(BF112),0, VLOOKUP(BF112,calculations!$C$8:$D$21,2,0)),BF112)+IFERROR(IF(ISBLANK(BK112),0, VLOOKUP(BK112,calculations!$C$8:$D$21,2,0)),BK112)+BP112)) | BT112: FALSE | BV112: FALSE | BX112: =IFERROR(Ceiling(VLOOKUP('PAGE 1'!AS112, datasheet!$O$8:$U$40,7,FALSE)*LOOKUP($CS$43,calculations!$A$63:$A$68,calculations!$B$63:$B$68),1),"") | CM112: FALSE | DA112: =IF(AND(ISBLANK(CO112),ISBLANK(CT112),ISBLANK(CY112)),"",(IFERROR(IF(ISBLANK(CO112),0, VLOOKUP(CO112,calculations!$C$8:$D$21,2,0)),CO112)+IFERROR(IF(ISBLANK(CT112),0, VLOOKUP(CT112,calculations!$C$8:$D$21,2,0)),CT112)+CY112)) | DC112: FALSE | DE112: FALSE | DG112: =IFERROR(Ceiling(VLOOKUP('PAGE 1'!CB112,datasheet!$F$49:$L$59,7,FALSE)*LOOKUP($CS$43,calculations!$A$63:$A$68,calculations!$B$63:$B$68),1),"")
BD115: FALSE | BR115: =IF(AND(ISBLANK(BF115),ISBLANK(BK115),ISBLANK(BP115)),"",(IFERROR(IF(ISBLANK(BF115),0, VLOOKUP(BF115,calculations!$C$8:$D$21,2,0)),BF115)+IFERROR(IF(ISBLANK(BK115),0, VLOOKUP(BK115,calculations!$C$8:$D$21,2,0)),BK115)+BP115)) | BT115: FALSE | BV115: FALSE | BX115: =IFERROR(Ceiling(VLOOKUP('PAGE 1'!AS115, datasheet!$O$8:$U$40,7,FALSE)*LOOKUP($CS$43,calculations!$A$63:$A$68,calculations!$B$63:$B$68),1),"") | CM115: FALSE | DA115: =IF(AND(ISBLANK(CO115),ISBLANK(CT115),ISBLANK(CY115)),"",(IFERROR(IF(ISBLANK(CO115),0, VLOOKUP(CO115,calculations!$C$8:$D$21,2,0)),CO115)+IFERROR(IF(ISBLANK(CT115),0, VLOOKUP(CT115,calculations!$C$8:$D$21,2,0)),CT115)+CY115)) | DC115: FALSE | DE115: FALSE | DG115: =IFERROR(Ceiling(VLOOKUP('PAGE 1'!CB115,datasheet!$F$49:$L$59,7,FALSE)*LOOKUP($CS$43,calculations!$A$63:$A$68,calculations!$B$63:$B$68),1),"")
C117: Active | O117: Spent | AA117: Available | AJ117: =AJ112-I117-U117 -> 7
...

Sheet PAGE 2
C3: Weapons & Equipment | AU3: formula | AY3: Pack 1 | BG3: =SUM(BK10:BN24)+SUM(CA10:CD24) -> 5 | BK3: Holds up to 20 ENC. When equipped adds ENC following worn armor rules (pg 77 CRB) plus 1 ENC for the pack itself. | CA3: Equip | CE3: pack 2 | CM3: =SUM(CQ10:CT24)+SUM(DG10:DJ24) -> 0 | CQ3: Holds up to 20 ENC. When equipped adds ENC following worn armor rules (pg 77 CRB) plus 1 ENC for the pack itself. | DG3: Equip
AU4: =IF(AI4<>"", VLOOKUP(AI4, calculations!$G$8:$H$136, 2, 0),"")
CA5: TRUE | DG5: FALSE
C7: Item | O7: ENC | S7: Item | AE7: ENC | AI7: Item | AU7: ENC | AY7: Item | BK7: ENC | BO7: Item | CA7: ENC | CE7: Item | CQ7: ENC | CU7: Item | DG7: ENC
C10: Shortspear | O10: =IF(C10<>"", VLOOKUP(C10, calculations!$G$8:$H$136, 2, 0),"") -> 2 | S10: Fish hooks (20) | AE10: =IF(S10<>"", VLOOKUP(S10, calculations!$G$8:$H$136, 2, 0),"") -> - | AU10: =IF(AI10<>"", VLOOKUP(AI10, calculations!$G$8:$H$136, 2, 0),"") | AY10: Waterskin or Canteen | BK10: =IF(AY10<>"", VLOOKUP(AY10, calculations!$G$8:$H$136, 2, 0),"") -> 1 | BO10: Game Snares and Traps | CA10: =IF(BO10<>"", VLOOKUP(BO10, calculations!$G$8:$H$136, 2, 0),"") -> 1 | CQ10: =IF(CE10<>"", VLOOKUP(CE10, calculations!$G$8:$H$136, 2, 0),"") | DG10: =IF(CU10<>"", VLOOKUP(CU10, calculations!$G$8:$H$136, 2, 0),"")
C13: Shortsword | O13: =IF(C13<>"", VLOOKUP(C13, calculations!$G$8:$H$136, 2, 0),"") -> 1 | S13: Flint & tinder | AE13: =IF(S13<>"", VLOOKUP(S13, calculations!$G$8:$H$136, 2, 0),"") -> - | AU13: =IF(AI13<>"", VLOOKUP(AI13, calculations!$G$8:$H$136, 2, 0),"") | AY13: Bedroll | BK13: =IF(AY13<>"", VLOOKUP(AY13, calculations!$G$8:$H$136, 2, 0),"") -> 1 | BO13: Cooking Pot | CA13: =IF(BO13<>"", VLOOKUP(BO13, calculations!$G$8:$H$136, 2, 0),"") -> 2 | CQ13: =IF(CE13<>"", VLOOKUP(CE13, calculations!$G$8:$H$136, 2, 0),"") | DG13: =IF(CU13<>"", VLOOKUP(CU13, calculations!$G$8:$H$136, 2, 0),"")
C16: Shield, Hoplite | O16: =IF(C16<>"", VLOOKUP(C16, calculations!$G$8:$H$136, 2, 0),"") -> 3 | S16: Lodestone | AE16: =IF(S16<>"", VLOOKUP(S16, calculations!$G$8:$H$136, 2, 0),"") -> - | AU16: =IF(AI16<>"", VLOOKUP(AI16, calculations!$G$8:$H$136, 2, 0),"") | BK16: =IF(AY16<>"", VLOOKUP(AY16, calculations!$G$8:$H$136, 2, 0),"") | CA16: =IF(BO16<>"", VLOOKUP(BO16, calculations!$G$8:$H$136, 2, 0),"") | CQ16: =IF(CE16<>"", VLOOKUP(CE16, calculations!$G$8:$H$136, 2, 0),"") | DG16: =IF(CU16<>"", VLOOKUP(CU16, calculations!$G$8:$H$136, 2, 0),"")
C19: Sling | O19: =IF(C19<>"", VLOOKUP(C19, calculations!$G$8:$H$136, 2, 0),"") -> - | S19: First aid kit | AE19: =IF(S19<>"", VLOOKUP(S19, calculations!$G$8:$H$136, 2, 0),"") -> - | AU19: =IF(AI19<>"", VLOOKUP(AI19, calculations!$G$8:$H$136, 2, 0),"") | BK19: =IF(AY19<>"", VLOOKUP(AY19, calculations!$G$8:$H$136, 2, 0),"") | CA19: =IF(BO19<>"", VLOOKUP(BO19, calculations!$G$8:$H$136, 2, 0),"") | CQ19: =IF(CE19<>"", VLOOKUP(CE19, calculations!$G$8:$H$136, 2, 0),"") | DG19: =IF(CU19<>"", VLOOKUP(CU19, calculations!$G$8:$H$136, 2, 0),"")
O22: =IF(C22<>"", VLOOKUP(C22, calculations!$G$8:$H$136, 2, 0),"") | S22: Mirror (hand glass) | AE22: =IF(S22<>"", VLOOKUP(S22, calculations!$G$8:$H$136, 2, 0),"") -> 1 | AU22: =IF(AI22<>"", VLOOKUP(AI22, calculations!$G$8:$H$136, 2, 0),"") | BK22: =IF(AY22<>"", VLOOKUP(AY22, calculations!$G$8:$H$136, 2, 0),"") | CA22: =IF(BO22<>"", VLOOKUP(BO22, calculations!$G$8:$H$136, 2, 0),"") | CQ22: =IF(CE22<>"", VLOOKUP(CE22, calculations!$G$8:$H$136, 2, 0),"") | DG22: =IF(CU22<>"", VLOOKUP(CU22, calculations!$G$8:$H$136, 2, 0),"")
C26: Equipment ENC | O26: =SUM(O10:R24)+SUM(AE10:AH24)+SUM(AU10:AX24)+IF(CA5,CEILING((SUM(BK10:BN24)+SUM(CA10:CD24))/2+1,1),0)+IF(DG5,CEILING((SUM(CQ10:CT24)+SUM(DG10:DJ24))/2+1,1),0) -> 11 | U26: Armour ENC (Equipped = ENC/2) | AQ26: =CEILING(SUM(AW40:BB67)/2,1) -> 13 | AW26: TOTAL ENC | BF26: =O26+AQ26 -> 24 | BL26: Condition | BU26: =IFS(TotalENC<=STR*2,"Unencumbered",TotalENC<=STR*3,"Burdened",TotalENC<STR*4,"Overloaded",TotalENC>=STR*4,"Immobile") -> Burdened | CI26: Armour Penalty (Armour ENC/5) | DF26: =CEILING(SUM(AW40:BB67)/5,1) -> 5
B32: Hit Locations | BE32: Fatigue | BV32: Movement
C37: d20 | H37: Location | P37: HP Max | V37: HP Cur | AC37: Armour Type | AQ37: AP | AW37: ENC | BW37: Movement Type | CP37: Move | CU37: Notes on Movement
BF38: Fresh | BQ38: TRUE
C40: 19-20 | H40: Head | P40: =Head -> 5 | AC40: Half Plate | AQ40: =IF(AC40<>"", VLOOKUP(AC40, calculations!$G$137:$I$144, 3, 0),"") -> 5 | AW40: =IF(AC40<>"", VLOOKUP(AC40, calculations!$G$137:$I$144, 2, 0),"") -> 4
BF41: Winded | BQ41: FALSE | BW41: Walk | CP41: =IFS(Burden="Unencumbered",'PAGE 1'!$AN$99,Burden="Burdened",'PAGE 1'!$AN$99-2,Burden="Overloaded",'PAGE 1'!$AN$99/2,Burden="Immobile",0)+IFS(BQ65=TRUE,-'PAGE 1'!$AN$99,BQ62=TRUE,-'PAGE 1'!$AN$99,BQ59=TRUE,-'PAGE 1'!$AN$99,BQ56=TRUE,-'PAGE 1'!$AN$99,BQ53=TRUE,-'PAGE 1'!$AN$99*0.5,BQ50=TRUE,-'PAGE 1'!$AN$99*0.5,BQ47=TRUE,-2,BQ44=TRUE,-1,BQ41=TRUE,0,BQ38=TRUE,0) -> 4
C44: 16-18 | H44: Left Arm | P44: =Arm -> 4 | AC44: Half Plate | AQ44: =IF(AC44<>"", VLOOKUP(AC44, calculations!$G$137:$I$144, 3, 0),"") -> 5 | AW44: =IF(AC44<>"", VLOOKUP(AC44, calculations!$G$137:$I$144, 2, 0),"") -> 4 | BF44: Tired | BQ44: FALSE | BW44: Run | CP44: =IF(((CP41+(INT(Athletics/25*0.5)))*3)-(ArmourPenalty)>0,((CP41+(INT(Athletics/25*0.5)))*3)-(ArmourPenalty),0) -> 7
BF47: Wearied | BQ47: FALSE | BW47: Sprint | CP47: =IF(((CP41+(INT(Athletics/25*0.5)))*5)-(ArmourPenalty)>0,((CP41+(INT(Athletics/25*0.5)))*5)-(ArmourPenalty),0) -> 15
C48: 13-15 | H48: Right Arm | P48: =Arm -> 4 | AC48: Half Plate | AQ48: =IF(AC48<>"", VLOOKUP(AC48, calculations!$G$137:$I$144, 3, 0),"") -> 5 | AW48: =IF(AC48<>"", VLOOKUP(AC48, calculations!$G$137:$I$144, 2, 0),"") -> 4
BF50: Exhausted | BQ50: FALSE | BW50: Jump | BZ50: Horizontal | CP50: =IF(CP41>0,(('PAGE 1'!CH11*2)+(INT(Athletics/20))-(ArmourPenalty/2))/100,0) -> 3.295
C52: 45270 | H52: Chest | P52: =Chest -> 7 | AC52: Half Plate | AQ52: =IF(AC52<>"", VLOOKUP(AC52, calculations!$G$137:$I$144, 3, 0),"") -> 5 | AW52: =IF(AC52<>"", VLOOKUP(AC52, calculations!$G$137:$I$144, 2, 0),"") -> 4
BF53: Debilitated | BQ53: FALSE | BZ53: Vertical | CP53: =IF(CP41>0,('PAGE 1'!CH11+(INT(Athletics/20)/5)-(ArmourPenalty))/100,0) -> 1.604
C56: 45176 | H56: Abdomen | P56: =Abdomen -> 6 | AC56: Padded/Quilted | AQ56: =IF(AC56<>"", VLOOKUP(AC56, calculations!$G$137:$I$144, 3, 0),"") -> 2 | AW56: =IF(AC56<>"", VLOOKUP(AC56, calculations!$G$137:$I$144, 2, 0),"") -> 1 | BF56: Incapacitated | BQ56: FALSE | BW56: Climb | BZ56: Rough or rugged surface | CP56: =IF(((CP41+Athletics)/10)-(ArmourPenalty/2)>0,((CP41+Athletics)/10)-(ArmourPenalty/2),0) -> 2.3
BF59: Semi-Conscious | BQ59: FALSE | BZ59: Steep surface | CP59: =IF(((CP41+Athletics)/15)-ArmourPenalty>0,((CP41+Athletics)/15)-ArmourPenalty,0) -> 0
C60: 45081 | H60: Left Leg | P60: =Leg -> 5 | AC60: Half Plate | AQ60: =IF(AC60<>"", VLOOKUP(AC60, calculations!$G$137:$I$144, 3, 0),"") -> 5 | AW60: =IF(AC60<>"", VLOOKUP(AC60, calculations!$G$137:$I$144, 2, 0),"") -> 4
BF62: Comatose | BQ62: FALSE | BZ62: Sheer surface | CP62: =IF(((CP41+Athletics)/30)-(ArmourPenalty*2)>0,((CP41+Athletics)/30)-(ArmourPenalty*2),0) -> 0
C64: 44986 | H64: Right Leg | P64: =Leg -> 5 | AC64: Half Plate | AQ64: =IF(AC64<>"", VLOOKUP(AC64, calculations!$G$137:$I$144, 3, 0),"") -> 5 | AW64: =IF(AC64<>"", VLOOKUP(AC64, calculations!$G$137:$I$144, 2, 0),"") -> 4
BF65: Dead | BQ65: FALSE | BW65: Swim | CP65: =((CP41+Swim)/12)-(ArmourPenalty*2) -> -7.6666667
C71: Combat Styles
C75: Style name | X75: Weapons | CS75: Trait
C78: Meerish Slinger | X78: Sling | AQ78: Sword | BI78: Shield
C82: Meerish Infantry | X82: Spear | AQ82: Shield | BI82: Javelin
C97: Weapons & Shields
C101: Melee weapons & shields | AB101: Damage | AK101: Size | AQ101: Reach | AW101: Traits | BW101: Combat Effects | CY101: AP | DE101: HP
C104: Shortspear | AB104: =(IF(C104<>"", VLOOKUP(C104, calculations!$G$73:$O$117, 3, 0),"")) -> 1d8+1 | AK104: =IF(C104<>"", VLOOKUP(C104, calculations!$G$73:$O$117, 4, 0),"") -> M | AQ104: =IF(C104<>"", VLOOKUP(C104, calculations!$G$73:$O$117, 5, 0),"") -> L | AW104: =IF(C104<>"", VLOOKUP(C104, calculations!$G$73:$O$117, 6, 0),"") -> Set, Thrown | BW104: =IF(C104<>"", VLOOKUP(C104, calculations!$G$73:$O$117, 7, 0),"") -> Impale | CY104: =IF(C104<>"", VLOOKUP(C104, calculations!$G$73:$O$117, 8, 0),"") -> 4 | DE104: =IF(C104<>"", VLOOKUP(C104, calculations!$G$73:$O$117, 9, 0),"") -> 5
C108: Shortsword | AB108: =(IF(C108<>"", VLOOKUP(C108, calculations!$G$73:$O$117, 3, 0),"")) -> 1d6 | AK108: =IF(C108<>"", VLOOKUP(C108, calculations!$G$73:$O$117, 4, 0),"") -> M | AQ108: =IF(C108<>"", VLOOKUP(C108, calculations!$G$73:$O$117, 5, 0),"") -> S | AW108: =IF(C108<>"", VLOOKUP(C108, calculations!$G$73:$O$117, 6, 0),"") | BW108: =IF(C108<>"", VLOOKUP(C108, calculations!$G$73:$O$117, 7, 0),"") -> Bleed, Impale | CY108: =IF(C108<>"", VLOOKUP(C108, calculations!$G$73:$O$117, 8, 0),"") -> 6 | DE108: =IF(C108<>"", VLOOKUP(C108, calculations!$G$73:$O$117, 9, 0),"") -> 8
C112: Shield, Hoplite | AB112: =(IF(C112<>"", VLOOKUP(C112, calculations!$G$73:$O$117, 3, 0),"")) -> 1d4 | AK112: =IF(C112<>"", VLOOKUP(C112, calculations!$G$73:$O$117, 4, 0),"") -> H | AQ112: =IF(C112<>"", VLOOKUP(C112, calculations!$G$73:$O$117, 5, 0),"") -> S | AW112: =IF(C112<>"", VLOOKUP(C112, calculations!$G$73:$O$117, 6, 0),"") -> Ranged Parry; Passive Blocks 4 locations | BW112: =IF(C112<>"", VLOOKUP(C112, calculations!$G$73:$O$117, 7, 0),"") -> Bash, Stun Location | CY112: =IF(C112<>"", VLOOKUP(C112, calculations!$G$73:$O$117, 8, 0),"") -> 6 | DE112: =IF(C112<>"", VLOOKUP(C112, calculations!$G$73:$O$117, 9, 0),"") -> 15
AB116: =(IF(C116<>"", VLOOKUP(C116, calculations!$G$73:$O$117, 3, 0),"")) | AK116: =IF(C116<>"", VLOOKUP(C116, calculations!$G$73:$O$117, 4, 0),"") | AQ116: =IF(C116<>"", VLOOKUP(C116, calculations!$G$73:$O$117, 5, 0),"") | AW116: =IF(C116<>"", VLOOKUP(C116, calculations!$G$73:$O$117, 6, 0),"") | BW116: =IF(C116<>"", VLOOKUP(C116, calculations!$G$73:$O$117, 7, 0),"") | CY116: =IF(C116<>"", VLOOKUP(C116, calculations!$G$73:$O$117, 8, 0),"") | DE116: =IF(C116<>"", VLOOKUP(C116, calculations!$G$73:$O$117, 9, 0),"")
AB120: =(IF(C120<>"", VLOOKUP(C120, calculations!$G$73:$O$117, 3, 0),"")) | AK120: =IF(C120<>"", VLOOKUP(C120, calculations!$G$73:$O$117, 4, 0),"") | AQ120: =IF(C120<>"", VLOOKUP(C120, calculations!$G$73:$O$117, 5, 0),"") | AW120: =IF(C120<>"", VLOOKUP(C120, calculations!$G$73:$O$117, 6, 0),"") | BW120: =IF(C120<>"", VLOOKUP(C120, calculations!$G$73:$O$117, 7, 0),"") | CY120: =IF(C120<>"", VLOOKUP(C120, calculations!$G$73:$O$117, 8, 0),"") | DE120: =IF(C120<>"", VLOOKUP(C120, calculations!$G$73:$O$117, 9, 0),"")
AB124: =(IF(C124<>"", VLOOKUP(C124, calculations!$G$73:$O$117, 3, 0),"")) | AK124: =IF(C124<>"", VLOOKUP(C124, calculations!$G$73:$O$117, 4, 0),"") | AQ124: =IF(C124<>"", VLOOKUP(C124, calculations!$G$73:$O$117, 5, 0),"") | AW124: =IF(C124<>"", VLOOKUP(C124, calculations!$G$73:$O$117, 6, 0),"") | BW124: =IF(C124<>"", VLOOKUP(C124, calculations!$G$73:$O$117, 7, 0),"") | CY124: =IF(C124<>"", VLOOKUP(C124, calculations!$G$73:$O$117, 8, 0),"") | DE124: =IF(C124<>"", VLOOKUP(C124, calculations!$G$73:$O$117, 9, 0),"")
C129: Ranged weapons | AB129: Damage | AK129: Force | AQ129: DM | AW129: Load | BC129: Impale | BI129: Range | BW129: Combat Effects | CY129: AP | DE129: HP
...

Sheet PAGE 3
C3: ANIMALS | BH3: ARMOR
C49: CLOTHING | BH49: PEOPLE
C95: TOOLS | BH95: VALUABLES & TREASURE
C141: VEHICLES | BH141: WEAPONS

Sheet CULTS
C3: Cult Information | AO3: Cult Information | CA3: Cult Information
C7: Ranks, Benefits, Restrictions, Gifts, Geasa | AO7: Ranks, Benefits, Restrictions, Gifts, Geasa | CA7: Ranks, Benefits, Restrictions, Gifts, Geasa
C10: Cult Name | AO10: Cult Name | CA10: Cult Name
C13: Cult Type | AO13: Cult Type | CA13: Cult Type
C16: Rank | R16: Title | X16: {=IF(AND(K13<>"",H16<>""),INDEX(calculations!$B$146:$G$151,MATCH(H16,calculations!$B$146:$B$151,0),MATCH(K13,calculations!$B$146:$G$146,0)),"")} | AO16: Rank | BD16: Title | BJ16: {=IF(AND(AW13<>"",AT16<>""),INDEX(calculations!$B$146:$G$151,MATCH(AT16,calculations!$B$146:$B$151,0),MATCH(AW13,calculations!$B$146:$G$146,0)),"")} | CA16: Rank | CP16: Title | CV16: {=IF(AND(CI13<>"",CF16<>""),INDEX(calculations!$B$146:$G$151,MATCH(CF16,calculations!$B$146:$B$151,0),MATCH(CI13,calculations!$B$146:$G$146,0)),"")}
C19: Benefits | AO19: Benefits | CA19: Benefits
C22: Restrictions | AO22: Restrictions | CA22: Restrictions
C25: Geasa | AO25: Geasa | CA25: Geasa
C28: Gifts | AO28: Gifts | CA28: Gifts
V31: Max MP | AD31: Current | BH31: Max MP | BP31: Current | CT31: Max MP | DB31: Current
C34: Devotional Pool | V34: =ROUNDUP(IF(K13="Theist Cult",IFS(X16="High Priest",CURRENT_POW,X16="Priest",CURRENT_POW*0.75,X16="Acolyte",CURRENT_POW*0.5,X16="Initiate",CURRENT_POW*0.25,X16="Lay Member",0),""),0) -> 0 | AO34: Devotional Pool | BH34: =ROUNDUP(IF(AW13="Theist Cult",IFS(BJ16="High Priest",CURRENT_POW,BJ16="Priest",CURRENT_POW*0.75,BJ16="Acolyte",CURRENT_POW*0.5,BJ16="Initiate",CURRENT_POW*0.25,BJ16="Lay Member",0),""),0) -> 0 | CA34: Devotional Pool | CT34: =ROUNDUP(IF(CI13="Theist Cult",IFS(CV16="High Priest",CURRENT_POW,CV16="Priest",CURRENT_POW*0.75,CV16="Acolyte",CURRENT_POW*0.5,CV16="Initiate",CURRENT_POW*0.25,CV16="Lay Member",0),""),0) -> 0
C43: Cult Information | AO43: Cult Information | CA43: Cult Information
C47: Ranks, Benefits, Restrictions, Gifts, Geasa | AO47: Ranks, Benefits, Restrictions, Gifts, Geasa | CA47: Ranks, Benefits, Restrictions, Gifts, Geasa
C50: Cult Name | AO50: Cult Name | CA50: Cult Name
C53: Cult Type | AO53: Cult Type | CA53: Cult Type
C56: Rank | R56: Title | X56: {=IF(AND(K53<>"",H56<>""),INDEX(calculations!$B$146:$G$151,MATCH(H56,calculations!$B$146:$B$151,0),MATCH(K53,calculations!$B$146:$G$146,0)),"")} | AO56: Rank | BD56: Title | BJ56: {=IF(AND(AW53<>"",AT56<>""),INDEX(calculations!$B$146:$G$151,MATCH(AT56,calculations!$B$146:$B$151,0),MATCH(AW53,calculations!$B$146:$G$146,0)),"")} | CA56: Rank | CP56: Title | CV56: {=IF(AND(CI53<>"",CF56<>""),INDEX(calculations!$B$146:$G$151,MATCH(CF56,calculations!$B$146:$B$151,0),MATCH(CI53,calculations!$B$146:$G$146,0)),"")}
C59: Benefits | AO59: Benefits | CA59: Benefits
C62: Restrictions | AO62: Restrictions | CA62: Restrictions
C65: Geasa | AO65: Geasa | CA65: Geasa
C68: Gifts | AO68: Gifts | CA68: Gifts
V71: Max MP | AD71: Current | BH71: Max MP | BP71: Current | CT71: Max MP | DB71: Current
C74: Devotional Pool | V74: =ROUNDUP(IF(K53="Theist Cult",IFS(X56="High Priest",CURRENT_POW,X56="Priest",CURRENT_POW*0.75,X56="Acolyte",CURRENT_POW*0.5,X56="Initiate",CURRENT_POW*0.25,X56="Lay Member",0),""),0) -> 0 | AO74: Devotional Pool | BH74: =ROUNDUP(IF(AW53="Theist Cult",IFS(BJ56="High Priest",CURRENT_POW,BJ56="Priest",CURRENT_POW*0.75,BJ56="Acolyte",CURRENT_POW*0.5,BJ56="Initiate",CURRENT_POW*0.25,BJ56="Lay Member",0),""),0) -> 0 | CA74: Devotional Pool | CT74: =ROUNDUP(IF(CI53="Theist Cult",IFS(CV56="High Priest",CURRENT_POW,CV56="Priest",CURRENT_POW*0.75,CV56="Acolyte",CURRENT_POW*0.5,CV56="Initiate",CURRENT_POW*0.25,CV56="Lay Member",0),""),0) -> 0
C83: Cult Information | AO83: Cult Information | CA83: Cult Information
C87: Ranks, Benefits, Restrictions, Gifts, Geasa | AO87: Ranks, Benefits, Restrictions, Gifts, Geasa | CA87: Ranks, Benefits, Restrictions, Gifts, Geasa
C90: Cult Name | AO90: Cult Name | CA90: Cult Name
C93: Cult Type | AO93: Cult Type | CA93: Cult Type
C96: Rank | R96: Title | X96: {=IF(AND(K93<>"",H96<>""),INDEX(calculations!$B$146:$G$151,MATCH(H96,calculations!$B$146:$B$151,0),MATCH(K93,calculations!$B$146:$G$146,0)),"")} | AO96: Rank | BD96: Title | BJ96: {=IF(AND(AW93<>"",AT96<>""),INDEX(calculations!$B$146:$G$151,MATCH(AT96,calculations!$B$146:$B$151,0),MATCH(AW93,calculations!$B$146:$G$146,0)),"")} | CA96: Rank | CP96: Title | CV96: {=IF(AND(CI93<>"",CF96<>""),INDEX(calculations!$B$146:$G$151,MATCH(CF96,calculations!$B$146:$B$151,0),MATCH(CI93,calculations!$B$146:$G$146,0)),"")}
C99: Benefits | AO99: Benefits | CA99: Benefits
C102: Restrictions | AO102: Restrictions | CA102: Restrictions
C105: Geasa | AO105: Geasa | CA105: Geasa
C108: Gifts | AO108: Gifts | CA108: Gifts
V111: Max MP | AD111: Current | BH111: Max MP | BP111: Current | CT111: Max MP | DB111: Current
C114: Devotional Pool | V114: =ROUNDUP(IF(K93="Theist Cult",IFS(X96="High Priest",CURRENT_POW,X96="Priest",CURRENT_POW*0.75,X96="Acolyte",CURRENT_POW*0.5,X96="Initiate",CURRENT_POW*0.25,X96="Lay Member",0),""),0) -> 0 | AO114: Devotional Pool | BH114: =ROUNDUP(IF(AW93="Theist Cult",IFS(BJ96="High Priest",CURRENT_POW,BJ96="Priest",CURRENT_POW*0.75,BJ96="Acolyte",CURRENT_POW*0.5,BJ96="Initiate",CURRENT_POW*0.25,BJ96="Lay Member",0),""),0) -> 0 | CA114: Devotional Pool | CT114: =ROUNDUP(IF(CI93="Theist Cult",IFS(CV96="High Priest",CURRENT_POW,CV96="Priest",CURRENT_POW*0.75,CV96="Acolyte",CURRENT_POW*0.5,CV96="Initiate",CURRENT_POW*0.25,CV96="Lay Member",0),""),0) -> 0
C123: Cult Information | AO123: Cult Information | CA123: Cult Information
C127: Ranks, Benefits, Restrictions, Gifts, Geasa | AO127: Ranks, Benefits, Restrictions, Gifts, Geasa | CA127: Ranks, Benefits, Restrictions, Gifts, Geasa
C130: Cult Name | AO130: Cult Name | CA130: Cult Name
C133: Cult Type | AO133: Cult Type | CA133: Cult Type
C136: Rank | R136: Title | X136: {=IF(AND(K133<>"",H136<>""),INDEX(calculations!$B$146:$G$151,MATCH(H136,calculations!$B$146:$B$151,0),MATCH(K133,calculations!$B$146:$G$146,0)),"")} | AO136: Rank | BD136: Title | BJ136: {=IF(AND(AW133<>"",AT136<>""),INDEX(calculations!$B$146:$G$151,MATCH(AT136,calculations!$B$146:$B$151,0),MATCH(AW133,calculations!$B$146:$G$146,0)),"")} | CA136: Rank | CP136: Title | CV136: {=IF(AND(CI133<>"",CF136<>""),INDEX(calculations!$B$146:$G$151,MATCH(CF136,calculations!$B$146:$B$151,0),MATCH(CI133,calculations!$B$146:$G$146,0)),"")}
C139: Benefits | AO139: Benefits | CA139: Benefits
C142: Restrictions | AO142: Restrictions | CA142: Restrictions
...

Sheet Special Effects Summary
A1: Special Effects Summary
B2: Offensive | C2: Defensive | D2: Specific Weapon Type | E2: Specific Roll | F2: Stackable
A3: Accidental Injury | C3: X | E3: Attacker Fumbles
A4: Arise | C4: X
A5: Bash | B5: X | D5: Shields or Bludgeoning
A6: Bleed | B6: X | D6: Cutting Weapons
A7: Blind Opponent | C7: X | E7: Defender Criticals
A8: Bypass Armour | B8: X | E8: Attacker Criticals | F8: X
A9: Choose Location | B9: X | E9: See Description
A10: Circumvent Cover | B10: X | D10: Ranged Weapons
A11: Circumvent Parry | B11: X | E11: Attacker Criticals
A12: Close Range | B12: X | C12: X
A13: Compel Surrender | B13: X | C13: X
A14: Damage Weapon | B14: X | C14: X
A15: Disarm Opponent | B15: X | C15: X
A16: Drop Foe | B16: X | D16: Siege Weapons, Firearms
